Workbook

Sheet PERGOLA
A6: PRO-FORMA | E6: FECHA: | F6: =TODAY() -> 46308
A7: Señores: | C7: A QUIEN CORRESPONDA | E7: Nro.: | F7: 000
A8: Ciudad: | C8: SANTA CRUZ DE LA SIERRA
A9: ITEM | B9: CANT. | C9: UNIDAD | D9: DETALLE DEL PROCESO | E9: PRECIO UNITARIO | F9: TOTAL
D10: Instalación y montaje de Pérgola
A11: 1 | B11: 1 | C11: und | D11: ARMADO Y MONTAJE -Trazado y corte de los perfiles y tubo cuadrado segun disposicion en planos. -Fabricacion de la cubierta interna de la pergola con perfil y soldadura GMAW. -Fabricacion de la viga metalica con tubo cuadrado de acero al carbon y soldadura GMAW. -Preparacion de los fijadores y anclajes. -Pintado de las serchas, correas y la viga metalica. -Fabricación de todas las piezas para las canaletas de desagüe. -Montaje de la viga metalica in situ con pernos de expansion. -Montaje de la estructura de cubierta in situ, fijacion a los muros con pernos de expansion. -Armado de las piezas y montaje de las canaletas de desagüe. -Montaje de las calaminas a la estructura de cubierta con tornillos autoperforantes. -Montaje del parapeto con plancha de acero al carbon de 1mm de espesor y tubo rectangular 30x40mm. -Pintado de todo el parapeto. -Instalarción de los paneles PVC con los elementos empotrantes en la estructura de cubierta y en los muros. -Instalacion de circuito electrico de iluminacion y montaje de luminarias. | E11: =conteo!E16 -> 4620 | F11: =E11*B11 -> 4620
A12: Materiales a Emplear para el Proceso
A13: Cubierta
A14: =A11+1 -> 2 | B14: =conteo!E11 -> 2 | C14: und | D14: Tubo cuadrado de acero al carbon 100x100mm e=2mm L=6 m | E14: 251 | F14: =B14*E14 -> 502
A15: =A14+1 -> 3 | B15: =conteo!E7 -> 8 | C15: und | D15: Perfil C de acero al carbon 25x50x2 mm L=6 m | E15: =IFERROR(_xlfn.XLOOKUP(D15,Materiales!$D$1:$D$93,Materiales!$E$1:$E$93),"") -> 118.5 | F15: =B15*E15 -> 948
A16: =A15+1 -> 4 | B16: =conteo!E6 -> 2 | C16: und | D16: Tubo rectangular de acero al carbon 100x50mm e=1.6mm L=6 m | E16: =IFERROR(_xlfn.XLOOKUP(D16,Materiales!$D$1:$D$93,Materiales!$E$1:$E$93),"") -> 400.5 | F16: =IF(E16="","",B16*E16) -> 801
A17: =A16+1 -> 5 | B17: =conteo!E12 -> 7 | C17: und | D17: Plegado perfil U 5x30x5 cm e=2mm | E17: =IFERROR(_xlfn.XLOOKUP(D17,Materiales!$D$1:$D$93,Materiales!$E$1:$E$93),"") -> 140 | F17: =B17*E17 -> 980
A18: =A17+1 -> 6 | B18: =conteo!E8 -> 31 | C18: m2 | D18: Chapa de calamina trapezoidal pintada 6x0.9m e=0.40mm | E18: =IFERROR(_xlfn.XLOOKUP(D18,Materiales!$D$1:$D$93,Materiales!$E$1:$E$93),"") -> 62.7 | F18: =B18*E18 -> 1943.7
A19: =A18+1 -> 7 | B19: =12*B18 -> 372 | C19: und | D19: Tornillos autoperforantes de 2" | E19: 0.4 | F19: =B19*E19 -> 148.8
A20: =A19+1 -> 8 | B20: =conteo!E10 -> 2 | C20: m | D20: membrana asfaltica 20 cm x 10 m | E20: 190 | F20: =B20*E20 -> 380
A21: =A20+1 -> 9 | B21: {=ROUND((Tabla2[Medidas m2]/50)+0.5,0)} -> 1 | C21: und | D21: Recuplast 3.6 Ltrs + membrana tela | E21: 180 | F21: =B21*E21 -> 180
A22: =A21+1 -> 10 | B22: {=ROUND((Tabla2[Medidas m2]/50)+0.5,0)} -> 1 | C22: und | D22: Insumos de soldadura GMAW (Electrodos E7018, E6016), pintura, discos de desbaste y corte, cinta aislante, pernos, gasolina, tiner, etc.) transporte | E22: 1800 | F22: =E22*B22 -> 1800
A23: Canaletas
A24: =A22+1 -> 11 | B24: =ROUND(conteo!B3,0) -> 6 | C24: m | D24: Canaleta de desagüe corte 50 | E24: 140 | F24: =B24*E24 -> 840
A25: =A24+1 -> 12 | C25: m | D25: Canaleta cubre bordes | E25: 150 | F25: 1180
A26: =A24+1 -> 12 | C26: und | D26: Ducto bajante alternativo pvc 3'' L=4m | E26: 65 | F26: =B26*E26 -> 0
A27: =A26+1 -> 13 | C27: und | D27: Codo 90 grados bajante pvc 3'' | E27: 10 | F27: =B27*E27 -> 0
A28: Cielo falso PVC
A29: =A26+1 -> 13 | B29: =conteo!E9 -> 18 | C29: und | D29: tablas de cielo falso PVC marron oscuro 25cmx8mmx5.95m | E29: 78 | F29: =B29*E29 -> 1404
A30: =A29+1 -> 14 | B30: =conteo!E13 -> 11 | C30: und | D30: Tubo cuadrado de acero al carbon 20x20x0.8 mm L=6 m | E30: =IFERROR(_xlfn.XLOOKUP(D30,Materiales!$D$1:$D$93,Materiales!$E$1:$E$93),"") -> 34 | F30: =B30*E30 -> 374
A31: =A30+1 -> 15 | B31: =conteo!E14 -> 2 | C31: und | D31: Aislante termico doble cara aluminizada de 10 mm | E31: =22.5*20 -> 450 | F31: =B31*E31 -> 900
A32: =A31+1 -> 16 | B32: 1 | C32: und | D32: Union H L=6m | E32: 50 | F32: =B32*E32 -> 50
A33: =A32+1 -> 17 | B33: =(B29*B30) -> 198 | C33: und | D33: Tornillo broca T2 bolsa | E33: 0.1 | F33: =B33*E33 -> 19.8
A34: Iluminación
A35: =A33+1 -> 18 | B35: {=ROUND(Tabla2[Medidas m2]/4+0.5,0)} -> 6 | C35: und | D35: Luminarias de empotar LED 18w | E35: 35 | F35: =B35*E35 -> 210
A36: =A35+1 -> 19 | B36: =B35*12 -> 72 | C36: m | D36: Cable Nro.14 AWG 1.5mm | E36: 3 | F36: =B36*E36 -> 216
A37: =A36+1 -> 20 | B37: 1 | C37: und | D37: Interruptor doble o simple | E37: 25 | F37: =B37*E37 -> 25 | I37: CUADRO | J37: COMPARATIVO
A38: =A37+1 -> 21 | B38: =B35+1 -> 7 | C38: und | D38: Cajas octogonales y rectangulares, cinta aislante, alambre, etc | E38: 8 | F38: =B38*E38 -> 56 | I38: precio | J38: 600 | K38: 650 | L38: 700 | M38: 750 | N38: 800
A39: Costo en Bolivianos | E39: Bs | F39: =SUM(F11:F38) -> 17578.3 | I39: Luis | J39: {=Tabla2[Medidas m2]*600} -> 14040 | K39: {=+Tabla2[Medidas m2]*650} -> 15210 | L39: {=+Tabla2[Medidas m2]*700} -> 16380 | M39: {=+Tabla2[Medidas m2]*750} -> 17550 | N39: {=+Tabla2[Medidas m2]*800} -> 18720
A40: Costo en Dólares | E40: $us | F40: =F39/6.96 -> 2525.6178 | I40: Materiales | J40: =+F39-E11 -> 12958.3
A41: Costo de venta | E41: Bs. | F41: =F39*1.1 -> 19336.13
A42: ="Area de la pérgola "&conteo!A3&" m2" -> Area de la pérgola 23,4 m2
A43: Tiempo de fabricación y montaje: | D43: =(conteo!D16)&" Días" -> 14 Días
A44: Datos Proveedor:
A45: Nombre:
...

Sheet conteo
A1: PERGOLA
A2: Medidas m2 | B2: Largo m | C2: Ancho m | D2: alto | E2: Empotramiento
A3: =B3*C3 -> 23.4 | B3: 6 | C3: 3.9 | D3: 3 | E3: muro | I3: ojo largo paralelo a canaleta
A5: Material | B5: Largo | C5: Ancho | D5: Cantidad | E5: Cantidad material
A6: Viga par cuerda sup. | B6: =ROUND((B3/2.5)+0.5,0) -> 3 | C6: {=SQRT((Tabla2[Ancho m]^2)+(0.16^2))} -> 3.9032807 | D6: =Tabla1[[#This Row],[Largo]]*Tabla1[[#This Row],[Ancho]] -> 11.709842 | E6: =ROUND(((Tabla1[[#This Row],[Cantidad]]/6)+0.5),0) -> 2
A7: Correa | B7: {=Tabla2[Largo m]} -> 6 | C7: =ROUND((C3/0.6)+0.5,0) -> 7 | D7: =Tabla1[[#This Row],[Largo]]*Tabla1[[#This Row],[Ancho]] -> 42 | E7: =ROUND((D7/6)+0.5,0) -> 8
A8: Cubierta o cerramiento | B8: =ROUND((B3/0.8)+0.5,0) -> 8 | C8: {=(SQRT((Tabla2[Ancho m]^2)+(0.16^2))-0.05)} -> 3.8532807 | E8: =ROUND((B8*Tabla1[[#This Row],[Ancho]])+0.5,0) -> 31
A9: Cielo falso Pvc | B9: {=(Tabla2[Largo m]/5.95)+0.1} -> 1.1084034 | C9: {=ROUND((Tabla2[Ancho m]/0.25)+0.5,0)} -> 16 | E9: =ROUND(Tabla1[[#This Row],[Largo]]*Tabla1[[#This Row],[Ancho]]+0.5,0) -> 18
A10: membrana asfaltica | B10: =B3 -> 6 | C10: =C3*2 -> 7.8 | D10: =ROUND((Tabla1[[#This Row],[Ancho]]+Tabla1[[#This Row],[Largo]])+0.5,0) -> 14 | E10: =ROUND((Tabla1[[#This Row],[Cantidad]]/10)+0.5,0) -> 2
A11: Parantes | B11: {=ROUND(Tabla2[Largo m]/3,0)} -> 2 | C11: {=ROUND(Tabla2[Ancho m]/3,0)} -> 1 | D11: {=IF(Tabla2[Empotramiento]="muro",1,IF(Tabla2[Empotramiento]="ambos",2,""))} -> 1 | E11: =(Tabla1[[#This Row],[Largo]]*Tabla1[[#This Row],[Cantidad]])+((Tabla1[[#This Row],[Ancho]]-1)*2) -> 2
A12: Cenefa Viga U Alero correa tirante | B12: {=Tabla2[Largo m]*2} -> 12 | C12: {=Tabla2[Ancho m]*2} -> 7.8 | D12: =Tabla1[[#This Row],[Largo]]+Tabla1[[#This Row],[Ancho]] -> 19.8 | E12: =ROUND(Tabla1[[#This Row],[Cantidad]]/3+0.5,0) -> 7
A13: soporte de cielo falso tubo 20x20 | B13: {=Tabla2[Largo m]} -> 6 | C13: =ROUND((C3/0.4)+0.5,0) -> 10 | D13: =C13*Tabla1[[#This Row],[Largo]] -> 60 | E13: =ROUND((D13/6)+0.5,0) -> 11
A14: aislante alum | B14: =ROUND((B3+0.5),0) -> 7 | C14: {=Tabla2[Ancho m]} -> 3.9 | D14: =B14*C14 -> 27.3 | E14: =ROUND((D14/20)+0.5,0) -> 2
A15: corniza U | B15: =B3*2 -> 12 | C15: =C3*2 -> 7.8 | D15: =B15+C15 -> 19.8 | E15: =ROUND((D15/6)+0.5,0) -> 4
A16: M.O. 2=maestro; 1=ayudante | B16: =200*Tabla1[[#This Row],[Cantidad]] -> 2800 | C16: =Tabla1[[#This Row],[Cantidad]]*130 -> 1820 | D16: {=IF(Tabla2[Medidas m2]<40,14,IF((40<Tabla2[Medidas m2]),21,""))} -> 14 | E16: =Tabla1[[#This Row],[Largo]]+Tabla1[[#This Row],[Ancho]] -> 4620
A18: CUBIERTA
A19: Material | B19: Largo | C19: Ancho | D19: Cantidad | E19: Cantidad material
A20: Perfil C 100x50 | B20: =ROUND((B17/2.5)+0.5,0) -> 1 | C20: {=Tabla2[Ancho m]} -> 3.9 | D20: =Tabla14[[#This Row],[Largo]]*Tabla14[[#This Row],[Ancho]] -> 3.9 | E20: =ROUND(((Tabla14[[#This Row],[Cantidad]]/6)+0.5),0) -> 1
A21: Perfil C 50x25 | B21: {=Tabla2[Largo m]} -> 6 | C21: =ROUND((C17/0.6)+0.5,0) -> 1 | D21: =Tabla14[[#This Row],[Largo]]*Tabla14[[#This Row],[Ancho]] -> 6 | E21: =ROUND((D21/6)+0.5,0) -> 2
A22: Calamina | B22: =ROUND((B17/0.8)+0.5,0) -> 1 | C22: {=Tabla2[Ancho m]} -> 3.9 | E22: =ROUND((B22*Tabla14[[#This Row],[Ancho]])+0.5,0) -> 4
A23: PVC | B23: {=(Tabla2[Largo m]/5.95)+0.1} -> 1.1084034 | C23: {=ROUND((Tabla2[Ancho m]/0.25)+0.5,0)} -> 16 | D23: =Tabla14[[#This Row],[Largo]]*Tabla14[[#This Row],[Ancho]] -> 17.734454 | E23: =ROUND(Tabla14[[#This Row],[Cantidad]]+0.5,0) -> 18
A24: membrana asfaltica | B24: =B17 -> 0 | C24: =C17*2 -> 0 | D24: =ROUND((Tabla14[[#This Row],[Ancho]]+Tabla14[[#This Row],[Largo]])+0.5,0) -> 1 | E24: =ROUND((Tabla14[[#This Row],[Cantidad]]/10)+0.5,0) -> 1
A25: Parantes 15x15 | E25: =B25+C25 -> 0
A26: perfil U | B26: {=ROUND(((Tabla2[Largo m]/3)*2)+0.5,0)} -> 5 | C26: {=ROUND(((Tabla2[Ancho m]/3)*2)+0.5,0)} -> 3 | D26: =Tabla14[[#This Row],[Largo]]+Tabla14[[#This Row],[Ancho]] -> 8 | E26: =+Tabla14[[#This Row],[Cantidad]] -> 8
A27: Plancha 1.2 m | B27: =D26*0.35 -> 2.8 | C27: =E25*0.6 -> 0 | D27: =ROUND((B27+C27)+0.5,0) -> 3 | E27: =ROUND((D27/1.2)+0.5,0) -> 3
A28: tubo 20x20 | B28: {=Tabla2[Largo m]} -> 6 | C28: =ROUND((C17/0.4)+0.5,0) -> 1 | D28: =C28*Tabla14[[#This Row],[Largo]] -> 6 | E28: =ROUND((D28/6)+0.5,0) -> 2
A29: aislante alum | B29: =ROUND((B17+0.5),0) -> 1 | C29: =ROUND((C17+0.5),0) -> 1 | D29: =B29*C29 -> 1 | E29: =ROUND((D29/20)+0.5,0) -> 1
A30: corniza U | B30: =B17*2 -> 0 | C30: =C17*2 -> 0 | D30: =B30+C30 -> 0 | E30: =ROUND((D30/6)+0.5,0) -> 1
A31: Parantes 20x20 | E31: =B31+C31 -> 0
A32: Policarbonato2.1x5.8 | B32: {=Tabla2[Largo m]/5} -> 1.2 | C32: {=Tabla2[Ancho m]/2.1} -> 1.8571429 | D32: =Tabla14[[#This Row],[Largo]]+Tabla14[[#This Row],[Ancho]] -> 3.0571429 | E32: =ROUND(Tabla14[[#This Row],[Cantidad]]+0.5,0) -> 4
A33: Viga frontal
A34: Viga trasera
A37: PERGOLA/POLICARBONATO
A38: Material | B38: Largo | C38: Ancho | D38: Cantidad | E38: Cantidad material
A39: Perfil C 100x50 | B39: =ROUND((B36/2.5)+0.5,0) -> 1 | C39: {=Tabla2[Ancho m]} -> 3.9 | D39: =Tabla145[[#This Row],[Largo]]*Tabla145[[#This Row],[Ancho]] -> 3.9 | E39: =ROUND(((Tabla145[[#This Row],[Cantidad]]/6)+0.5),0) -> 1
A40: Perfil C 50x25 | B40: {=Tabla2[Largo m]} -> 6 | C40: =ROUND((C36/0.6)+0.5,0) -> 1 | D40: =Tabla145[[#This Row],[Largo]]*Tabla145[[#This Row],[Ancho]] -> 6 | E40: =ROUND((D40/6)+0.5,0) -> 2
A41: Calamina | B41: =ROUND((B36/0.8)+0.5,0) -> 1 | C41: {=Tabla2[Ancho m]} -> 3.9 | E41: =ROUND((B41*Tabla145[[#This Row],[Ancho]])+0.5,0) -> 4
A42: PVC | B42: {=(Tabla2[Largo m]/5.95)+0.1} -> 1.1084034 | C42: {=ROUND((Tabla2[Ancho m]/0.25)+0.5,0)} -> 16 | D42: =Tabla145[[#This Row],[Largo]]*Tabla145[[#This Row],[Ancho]] -> 17.734454 | E42: =ROUND(Tabla145[[#This Row],[Cantidad]]+0.5,0) -> 18
A43: membrana asfaltica | B43: =B36 -> 0 | C43: =C36*2 -> 0 | D43: =ROUND((Tabla145[[#This Row],[Ancho]]+Tabla145[[#This Row],[Largo]])+0.5,0) -> 1 | E43: =ROUND((Tabla145[[#This Row],[Cantidad]]/10)+0.5,0) -> 1
A44: Parantes 15x15 | E44: =B44+C44 -> 0
...

Sheet Materiales
A1: Materiales a Emplear para el Proceso
A2: 1
A3: =A2+1 -> 2 | B3: =conteo!E6 -> 2 | C3: und | D3: Perfil C galvanizado 100x50x1.8 mm L=6 m | E3: 269 | F3: Actualizado13/9/26
A4: =A3+1 -> 3 | B4: =conteo!E6 -> 2 | C4: und | D4: Perfil C de acero al carbon 100x50x2 mm L=6 m | E4: 246
A5: =A4+1 -> 4 | B5: 0 | C5: und | D5: Perfil C Galvanizado 40x80x1.8 mm L=6 m | E5: 214
A6: =A5+1 -> 5 | B6: =conteo!E6 -> 2 | C6: und | D6: Perfil C Galvanizado 25x50x1.5 mm L=6 m | E6: 129
A7: =A6+1 -> 6 | B7: 0 | C7: und | D7: Perfil C Galvanizado 25x50x1.8 mm L=6 m | E7: 118
A8: =A7+1 -> 7 | B8: =conteo!E7 -> 8 | C8: und | D8: Perfil C de acero al carbon 25x50x2 mm L=6 m | E8: 118.5
A9: =A8+1 -> 8 | B9: =conteo!E8 -> 31 | C9: und | D9: Perfil C de acero al carbon 25x50x1.8 mm L=6 m | E9: 112.5
A10: =A9+1 -> 9 | B10: =conteo!E11 -> 2 | C10: und | D10: Plegado de tubos 15x15 cm union en cara e=2mm L=3m | E10: 536
A11: =A10+1 -> 10 | B11: =Tabla1[[#This Row],[Cantidad material]] -> 2 | C11: und | D11: Plegado de tubos 20x20 cm union en cara e=2mm L=3m | E11: 696
A12: =A11+1 -> 11 | B12: =conteo!D12 -> 19.8 | C12: und | D12: Plegado perfil U 5x25x5 cm e=2mm | E12: 300
A13: =A12+1 -> 12 | B13: =conteo!#REF! -> #REF! | C13: und | D13: Plegado perfil U 5x30x5 cm e=2mm | E13: 140
A14: =A12+1 -> 12 | B14: 0 | C14: und | D14: Plancha negra 1,2x3m de e=2 mm | E14: 740
A15: =A14+1 -> 13 | B15: 0 | C15: und | D15: Plancha negra 1x2m de e=3 mm | E15: 630
A16: =A15+1 -> 14 | B16: 0 | C16: und | D16: Plancha negra 1.5x3m de e=1.5 mm | E16: 660
A17: =A18+1 -> 16 | B17: 0 | C17: und | D17: Plancha negra 1.5x3m de e=1 mm | E17: 590
A18: =A16+1 -> 15 | B18: 0 | C18: und | D18: Plancha negra antideslizante 1.2x3m de e=3 mm | E18: 1450
A19: =A17+1 -> 17 | B19: 0 | C19: und | D19: Plancha negra antideslizante 1.2x3m de e=2 mm | E19: 956
A20: =A18+1 -> 16 | B20: 0 | C20: und | D20: Tubo cuadrado de acero al carbon 100x100mm e=3mm L=6 m | E20: 797
A21: =A20+1 -> 17 | B21: 0 | C21: und | D21: Tubo cuadrado de acero al carbon 100x100mm e=2mm L=6 m | E21: 524
A22: =A21+1 -> 18 | B22: 0 | C22: und | D22: Tubo cuadrado de acero al carbon 100x100mm e=1.6mm L=6 m | E22: 407
A23: =A22+1 -> 19 | B23: 0 | C23: und | D23: Tubo rectangular de acero al carbon 100x50mm e=2mm L=6 m | E23: 429.5
A24: =A23+1 -> 20 | B24: 0 | C24: und | D24: Tubo rectangular de acero al carbon 100x50mm e=1.6mm L=6 m | E24: 400.5
A25: =A24+1 -> 21 | B25: 0 | C25: und | D25: Tubo rectangular de acero al carbon 40x80mm e=3mm L=6 m | E25: 495
A26: =A25+1 -> 22 | B26: 0 | C26: und | D26: Tubo rectangular de acero al carbon 40x80mm e=2mm L=6 m | E26: 201.5
A27: =A26+1 -> 23 | B27: 0 | C27: und | D27: Tubo rectangular de acero al carbon 40x80mm e=1.5mm L=6 m | E27: 196
A28: =A27+1 -> 24 | B28: 0 | C28: und | D28: Tubo rectangular de acero al carbon 40x80mm e=1.2mm L=6 m | E28: 153
A29: =A28+1 -> 25 | B29: 0 | C29: und | D29: Tubo rectangular de acero al carbon 30x70mm e=2mm L=6 m | E29: 228.5
A30: =A29+1 -> 26 | B30: 0 | C30: und | D30: Tubo rectangular de acero al carbon 30x70mm e=1.6mm L=6 m | E30: 208
A31: =A30+1 -> 27 | B31: 0 | C31: und | D31: Tubo rectangular de acero al carbon 30x70mm e=1.2mm L=6 m | E31: 162
A32: =A31+1 -> 28 | B32: 0 | C32: und | D32: Tubo rectangular de acero al carbon 50x50mm e=2mm L=6 m | E32: 221
... A49: =A48+1 -> 45 | B49: 0 | C49: und | D49: platino 2'' x 1/8'' | E49: 101
A50: =A49+1 -> 46 | B50: =conteo!E8 -> 31 | C50: m2 | D50: Chapa de calamina trapezoidal pintada 6x0.9m e=0.40mm | E50: 62.7
A51: =A50+1 -> 47 | B51: 0 | C51: und | D51: Lamina trapezoidal plastica 2.4m efectivo=0.8m | E51: 131
A52: =A51+1 -> 48 | B52: 0 | C52: und | D52: Lamina trapezoidal plastica 3m efectivo=0.8m | E52: 152
A53: =A52+1 -> 49 | B53: =conteo!E11 -> 2 | C53: und | D53: Lamina trapezoidal plastica 6m efectivo=0.8m | E53: 315
A54: =A50+1 -> 47 | B54: =conteo!E16 -> 4620 | C54: und | D54: Policarbonato alveolar de e=10 mm 2.1x5.8m | E54: 1505
A55: =A50+1 -> 47 | B55: 0 | C55: und | D55: Policarbonato solido de e=8 mm 1.22x2.44m | E55: 2029
A56: =A54+1 -> 48 | B56: =conteo!E17 -> 0 | C56: und | D56: Policarbonato solido de e=6 mm 1.22x2.44m | E56: 1521.89
...
